<?xml version="1.0"?>
<robot xmlns:xacro="http://www.ros.org/wiki/xacro">

    <xacro:include filename="inertial_macros.xacro"/>

    <material name="white">
        <color rgba="1 1 1 1" />
    </material>
    <material name="orange">
        <color rgba="1 0.3 0.1 1" />
    </material>
    <material name="blue">
        <color rgba="0.2 0.2 1 1" />
    </material>
    <material name="black">
        <color rgba="0 0 0 1" />
    </material>


  
    
 <!-- BASE LINK -->

 <link name="base_link">

 </link>

 <!-- BASE_FOOTPRINT LINK -->

 <joint name="base_footprint_joint" type="fixed">
    <parent link="base_link"/>
    <child link="base_footprint"/>
    <origin xyz="0 0 0" rpy="0 0 0"/> <!-- Adjust as needed -->
</joint>

<link name="base_footprint">
    <!-- Link properties -->
</link>
    <!-- Chassis Link-->
    <joint name="chassis_joint" type="fixed">
        <parent link="base_link" />
        <child link="chassis" />
        <origin xyz="-0.25 0.0 0.0" rpy="0.0 0.0 0.0" />

    </joint>

    <link name="chassis">
        <visual>
            <origin xyz="0.25 0 0.075"/>
            <geometry>
                <box size="0.5 0.3 0.12"/>
            </geometry>
            <material name="white"/>
        </visual>
        <collision>
            <origin xyz="0.25 0 0.075"/>
            <geometry>
                <box size="0.5 0.3 0.12"/>
            </geometry>
        </collision>
        <xacro:inertial_box mass="0.5" x="0.3" y="0.3" z="0.15">
            <origin xyz="0.15 0 0.075" rpy="0 0 0"/>
        </xacro:inertial_box>
    </link>
 

      <!-- LEFT WHEEL 2 LINK -->

      <joint name="left_wheel_joint_2" type="continuous">
        <parent link="base_link" />
        <child link="left_wheel_2" />
        <origin xyz="-0.125 0.175 0" rpy="-${pi/2} 0 0" />
        <axis xyz="0 0 1"/>
    </joint>

  
    <link name="left_wheel_2">
        <visual>
            <geometry>
                <cylinder radius="0.05" length="0.045"/>
            </geometry>
            <material name="blue"/>
        </visual>
        <collision>
            <geometry>
                <cylinder radius="0.05" length="0.045"/>
            </geometry>
        </collision>
        <xacro:inertial_cylinder mass="0.1" length="0.045" radius="0.05">
            <origin xyz="0 0 0" rpy="0 0 0"/>
        </xacro:inertial_cylinder>
    </link>

    
    <!-- LEFT WHEEL 1 LINK -->

    <joint name="left_wheel_joint_1" type="continuous">
        <parent link="base_link" />
        <child link="left_wheel_1" />
        <origin xyz="0.125 0.175 0" rpy="-${pi/2} 0 0" />
        <axis xyz="0 0 1"/>
    </joint>

    <link name="left_wheel_1">
        <visual>
            <geometry>
                <cylinder radius="0.05" length="0.045"/>
            </geometry>
            <material name="blue"/>
        </visual>
        <collision>
            <geometry>
                <cylinder radius="0.05" length="0.045"/>
            </geometry>
        </collision>
        <xacro:inertial_cylinder mass="0.1" length="0.045" radius="0.05">
            <origin xyz="0 0 0" rpy="0 0 0"/>
        </xacro:inertial_cylinder>
    </link>

  



    <!-- RIGHT WHEEL 2 LINK -->

    <joint name="right_wheel_joint_2" type="continuous">
        <parent link="base_link" />
        <child link="right_wheel_2" />
        <origin xyz="-0.125 -0.175 0" rpy="${-pi/2} 0 0" />
        <axis xyz="0 0 1"/>
    </joint>
    <link name="right_wheel_2">
        <visual>
            <geometry>
                <cylinder radius="0.05" length="0.045"/>
            </geometry>
            <material name="blue"/>
        </visual>
        <collision>
            <geometry>
                <cylinder radius="0.05" length="0.045"/>
            </geometry>
        </collision>
        <xacro:inertial_cylinder mass="0.1" length="0.045" radius="0.05">
            <origin xyz="0 0 0" rpy="0 0 0"/>
        </xacro:inertial_cylinder>
    </link>

   



      <!-- RIGHT WHEEL 1 LINK -->

      <joint name="right_wheel_joint_1" type="continuous">
        <parent link="base_link" />
        <child link="right_wheel_1" />
        <origin xyz="0.125 -0.175 0" rpy="${-pi/2} 0 0" />
        <axis xyz="0 0 1"/>
    </joint>
    <link name="right_wheel_1">
        <visual>
            <geometry>
                <cylinder radius="0.05" length="0.045"/>
            </geometry>
            <material name="blue"/>
        </visual>
        <collision>
            <geometry>
                <cylinder radius="0.05" length="0.045"/>
            </geometry>
        </collision>
        <xacro:inertial_cylinder mass="0.1" length="0.045" radius="0.05">
            <origin xyz="0 0 0" rpy="0 0 0"/>
        </xacro:inertial_cylinder>
    </link>


</robot>
